Workbook

Sheet Inicio
A1: LibrIA — Gestión del proyecto
A2: MVP de plataforma web literaria con ETL e IA
A4: Proyecto | B4: LibrIA — MVP de plataforma web literaria
A5: Duración | B5: 18 semanas en 3 fases (Fase 1: S1–S6 · Fase 2: S7–S12 · Fase 3: S13–S18)
A6: Metodología | B6: Ágil e incremental, 8 sprints de una a dos semanas gestionados en Jira (10 ago–25 nov 2026)
A7: Equipo | B7: Josyan Bonnemaison (Frontend / UX-UI) · Nicole Marchant (Backend, Base de Datos, Integraciones, ETL e IA) · Katherine Rubilar (Coordinación de Proyecto / Frontend)
A9: Contenido del libro
A10: Hoja | B10: Qué contiene
A11: EDT | B11: Estructura de desglose del trabajo: 6 paquetes y 30 entregables con responsables de ejecución (leídos desde la RACI), semanas y predecesoras. Es la fuente de las demás hojas.
A12: Diagrama EDT | B12: Diagrama jerárquico de la EDT, listo para la presentación.
A13: Roles | B13: Rol, responsabilidades y número de paquetes donde cada integrante aprueba (A) o ejecuta (R).
A14: RACI | B14: Quién ejecuta (R), aprueba y rinde cuentas (A), es consultado (C) o informado (I). El control verifica un único A y al menos un R; en Gestión (1.1) exige además que A y R estén separados.
A15: Gantt | B15: Cronograma de 18 semanas calculado desde la EDT, con responsables de ejecución y predecesoras.
A16: Criterios de riesgo | B16: Escalas de probabilidad e impacto, clasificación y estrategias de respuesta.
A17: Registro de riesgos | B17: 16 riesgos con puntuación, estrategia, acciones, disparador, responsable y campos de seguimiento de respuesta y riesgo residual.
A18: Mapa de calor | B18: Matriz probabilidad × impacto con los riesgos ubicados.
A19: RBS | B19: Estructura de desglose de riesgos por categoría, en tabla y diagrama.
A21: Control de versiones
A22: Versión | B22: Fecha | C22: Responsable | D22: Comentario
A23: 1.0 | B23: 46290 | C23: Katherine Rubilar | D23: Versión inicial: EDT, RACI, Gantt y gestión de riesgos
A24: 1.1 | B24: 46292 | C24: Katherine Rubilar | D24: Corrección de gobernanza del MVP: separación R/A, alcance de perfil lector, dependencias del cronograma y seguimiento de riesgos.
A25: 1.2 | B25: 46293 | C25: Katherine Rubilar | D25: RACI: A/R para el dueño de cada área técnica y separación A/R solo en gestión; carga de aprobación rebalanceada. EDT reconectada a la RACI, seguridad transversal S2–S12, fórmula y lista EDT restauradas en el registro.
A26: 1.3 | B26: 46313 | C26: Katherine Rubilar | D26: Ajustes de la Fase 2: Nicole ejecuta ETL e IA ; IA local con Ollama (R-08 actualizado).

Sheet EDT
A1: Estructura de desglose del trabajo (EDT)
A4: Código | B4: Nivel | C4: Paquete / entregable | D4: Producto esperado | E4: Responsable(s) de ejecución (R) | F4: Semana inicio | G4: Semana fin | H4: Duración (sem) | I4: Fase | J4: Predecesora(s)
A5: 1.0 | B5: 1 | C5: LibrIA — MVP Plataforma Web Literaria | D5: MVP integrado con ETL e IA, demostrado en la presentación final | E5: Equipo LibrIA | F5: =MIN(F6:F41) -> 1 | G5: =MAX(G6:G41) -> 18 | H5: =G5-F5+1 -> 18 | I5: =IF(F5>=13,"Fase 3",IF(G5<=6,"Fase 1",IF(AND(F5>=7,G5<=12),"Fase 2","Transversal"))) -> Transversal
A6: 1.1 | B6: 2 | C6: Gestión del proyecto | F6: =MIN(F7:F11) -> 1 | G6: =MAX(G7:G11) -> 18 | H6: =G6-F6+1 -> 18 | I6: =IF(F6>=13,"Fase 3",IF(G6<=6,"Fase 1",IF(AND(F6>=7,G6<=12),"Fase 2","Transversal"))) -> Transversal
A7: 1.1.1 | B7: 3 | C7: Definición de alcance y backlog del MVP | D7: Backlog cerrado del MVP y alcance dentro/fuera | E7: =MID(IF(RIGHT(RACI!C6,1)="R",", Josyan Bonnemaison","")&IF(RIGHT(RACI!D6,1)="R",", Nicole Marchant","")&IF(RIGHT(RACI!E6,1)="R",", Katherine Rubilar",""),3,200) -> Katherine Rubilar | F7: 1 | G7: 1 | H7: =G7-F7+1 -> 1 | I7: =IF(F7>=13,"Fase 3",IF(G7<=6,"Fase 1",IF(AND(F7>=7,G7<=12),"Fase 2","Transversal"))) -> Fase 1
A8: 1.1.2 | B8: 3 | C8: Plan de trabajo y carta Gantt | D8: Plan de trabajo y Gantt de 18 semanas | E8: =MID(IF(RIGHT(RACI!C7,1)="R",", Josyan Bonnemaison","")&IF(RIGHT(RACI!D7,1)="R",", Nicole Marchant","")&IF(RIGHT(RACI!E7,1)="R",", Katherine Rubilar",""),3,200) -> Katherine Rubilar | F8: 1 | G8: 1 | H8: =G8-F8+1 -> 1 | I8: =IF(F8>=13,"Fase 3",IF(G8<=6,"Fase 1",IF(AND(F8>=7,G8<=12),"Fase 2","Transversal"))) -> Fase 1 | J8: 1.1.1
A9: 1.1.3 | B9: 3 | C9: Asignación de roles y responsabilidades | D9: Matriz RACI y definición de roles | E9: =MID(IF(RIGHT(RACI!C8,1)="R",", Josyan Bonnemaison","")&IF(RIGHT(RACI!D8,1)="R",", Nicole Marchant","")&IF(RIGHT(RACI!E8,1)="R",", Katherine Rubilar",""),3,200) -> Katherine Rubilar | F9: 1 | G9: 1 | H9: =G9-F9+1 -> 1 | I9: =IF(F9>=13,"Fase 3",IF(G9<=6,"Fase 1",IF(AND(F9>=7,G9<=12),"Fase 2","Transversal"))) -> Fase 1 | J9: 1.1.1
A10: 1.1.4 | B10: 3 | C10: Gestión de riesgos | D10: Registro de riesgos, RBS y revisiones | E10: =MID(IF(RIGHT(RACI!C9,1)="R",", Josyan Bonnemaison","")&IF(RIGHT(RACI!D9,1)="R",", Nicole Marchant","")&IF(RIGHT(RACI!E9,1)="R",", Katherine Rubilar",""),3,200) -> Katherine Rubilar | F10: 1 | G10: 18 | H10: =G10-F10+1 -> 18 | I10: =IF(F10>=13,"Fase 3",IF(G10<=6,"Fase 1",IF(AND(F10>=7,G10<=12),"Fase 2","Transversal"))) -> Transversal | J10: 1.1.1
A11: 1.1.5 | B11: 3 | C11: Seguimiento y control del avance | D11: Reuniones de seguimiento y control de cambios | E11: =MID(IF(RIGHT(RACI!C10,1)="R",", Josyan Bonnemaison","")&IF(RIGHT(RACI!D10,1)="R",", Nicole Marchant","")&IF(RIGHT(RACI!E10,1)="R",", Katherine Rubilar",""),3,200) -> Katherine Rubilar | F11: 2 | G11: 18 | H11: =G11-F11+1 -> 17 | I11: =IF(F11>=13,"Fase 3",IF(G11<=6,"Fase 1",IF(AND(F11>=7,G11<=12),"Fase 2","Transversal"))) -> Transversal | J11: 1.1.2
A12: 1.2 | B12: 2 | C12: Análisis y diseño | F12: =MIN(F13:F18) -> 1 | G12: =MAX(G13:G18) -> 2 | H12: =G12-F12+1 -> 2 | I12: =IF(F12>=13,"Fase 3",IF(G12<=6,"Fase 1",IF(AND(F12>=7,G12<=12),"Fase 2","Transversal"))) -> Fase 1
A13: 1.2.1 | B13: 3 | C13: Requerimientos e historias de usuario | D13: ERS, historias de usuario y criterios de aceptación | E13: =MID(IF(RIGHT(RACI!C12,1)="R",", Josyan Bonnemaison","")&IF(RIGHT(RACI!D12,1)="R",", Nicole Marchant","")&IF(RIGHT(RACI!E12,1)="R",", Katherine Rubilar",""),3,200) -> Nicole Marchant, Katherine Rubilar | F13: 1 | G13: 1 | H13: =G13-F13+1 -> 1 | I13: =IF(F13>=13,"Fase 3",IF(G13<=6,"Fase 1",IF(AND(F13>=7,G13<=12),"Fase 2","Transversal"))) -> Fase 1 | J13: 1.1.1
A14: 1.2.2 | B14: 3 | C14: Modelado de procesos (BPMN) y casos de uso | D14: Diagrama BPMN y diagrama de casos de uso | E14: =MID(IF(RIGHT(RACI!C13,1)="R",", Josyan Bonnemaison","")&IF(RIGHT(RACI!D13,1)="R",", Nicole Marchant","")&IF(RIGHT(RACI!E13,1)="R",", Katherine Rubilar",""),3,200) -> Josyan Bonnemaison | F14: 1 | G14: 1 | H14: =G14-F14+1 -> 1 | I14: =IF(F14>=13,"Fase 3",IF(G14<=6,"Fase 1",IF(AND(F14>=7,G14<=12),"Fase 2","Transversal"))) -> Fase 1 | J14: 1.2.1
A15: 1.2.3 | B15: 3 | C15: Arquitectura del sistema | D15: Diagrama de arquitectura (monolito modular) | E15: =MID(IF(RIGHT(RACI!C14,1)="R",", Josyan Bonnemaison","")&IF(RIGHT(RACI!D14,1)="R",", Nicole Marchant","")&IF(RIGHT(RACI!E14,1)="R",", Katherine Rubilar",""),3,200) -> Nicole Marchant | F15: 1 | G15: 1 | H15: =G15-F15+1 -> 1 | I15: =IF(F15>=13,"Fase 3",IF(G15<=6,"Fase 1",IF(AND(F15>=7,G15<=12),"Fase 2","Transversal"))) -> Fase 1 | J15: 1.2.1
A16: 1.2.4 | B16: 3 | C16: Modelo de datos operacional y analítico | D16: Modelo ER y diccionario de datos | E16: =MID(IF(RIGHT(RACI!C15,1)="R",", Josyan Bonnemaison","")&IF(RIGHT(RACI!D15,1)="R",", Nicole Marchant","")&IF(RIGHT(RACI!E15,1)="R",", Katherine Rubilar",""),3,200) -> Nicole Marchant | F16: 2 | G16: 2 | H16: =G16-F16+1 -> 1 | I16: =IF(F16>=13,"Fase 3",IF(G16<=6,"Fase 1",IF(AND(F16>=7,G16<=12),"Fase 2","Transversal"))) -> Fase 1 | J16: 1.2.3
A17: 1.2.5 | B17: 3 | C17: Diseño UI/UX y mockups | D17: Wireframes, mockups y mapa de navegación | E17: =MID(IF(RIGHT(RACI!C16,1)="R",", Josyan Bonnemaison","")&IF(RIGHT(RACI!D16,1)="R",", Nicole Marchant","")&IF(RIGHT(RACI!E16,1)="R",", Katherine Rubilar",""),3,200) -> Josyan Bonnemaison | F17: 2 | G17: 2 | H17: =G17-F17+1 -> 1 | I17: =IF(F17>=13,"Fase 3",IF(G17<=6,"Fase 1",IF(AND(F17>=7,G17<=12),"Fase 2","Transversal"))) -> Fase 1 | J17: 1.2.1
A18: 1.2.6 | B18: 3 | C18: Contratos de API | D18: Especificación OpenAPI de endpoints | E18: =MID(IF(RIGHT(RACI!C17,1)="R",", Josyan Bonnemaison","")&IF(RIGHT(RACI!D17,1)="R",", Nicole Marchant","")&IF(RIGHT(RACI!E17,1)="R",", Katherine Rubilar",""),3,200) -> Nicole Marchant | F18: 2 | G18: 2 | H18: =G18-F18+1 -> 1 | I18: =IF(F18>=13,"Fase 3",IF(G18<=6,"Fase 1",IF(AND(F18>=7,G18<=12),"Fase 2","Transversal"))) -> Fase 1 | J18: 1.2.3, 1.2.4
A19: 1.3 | B19: 2 | C19: Desarrollo de la aplicación web | F19: =MIN(F20:F24) -> 3 | G19: =MAX(G20:G24) -> 7 | H19: =G19-F19+1 -> 5 | I19: =IF(F19>=13,"Fase 3",IF(G19<=6,"Fase 1",IF(AND(F19>=7,G19<=12),"Fase 2","Transversal"))) -> Transversal
A20: 1.3.1 | B20: 3 | C20: Autenticación, usuarios y perfil lector | D20: Registro, inicio de sesión y perfil lector básico funcional | E20: =MID(IF(RIGHT(RACI!C19,1)="R",", Josyan Bonnemaison","")&IF(RIGHT(RACI!D19,1)="R",", Nicole Marchant","")&IF(RIGHT(RACI!E19,1)="R",", Katherine Rubilar",""),3,200) -> Josyan Bonnemaison, Nicole Marchant | F20: 3 | G20: 3 | H20: =G20-F20+1 -> 1 | I20: =IF(F20>=13,"Fase 3",IF(G20<=6,"Fase 1",IF(AND(F20>=7,G20<=12),"Fase 2","Transversal"))) -> Fase 1 | J20: 1.2.3, 1.2.5, 1.2.6
A21: 1.3.2 | B21: 3 | C21: Catálogo y búsqueda de libros | D21: Búsqueda por título o autor | E21: =MID(IF(RIGHT(RACI!C20,1)="R",", Josyan Bonnemaison","")&IF(RIGHT(RACI!D20,1)="R",", Nicole Marchant","")&IF(RIGHT(RACI!E20,1)="R",", Katherine Rubilar",""),3,200) -> Josyan Bonnemaison, Nicole Marchant | F21: 4 | G21: 4 | H21: =G21-F21+1 -> 1 | I21: =IF(F21>=13,"Fase 3",IF(G21<=6,"Fase 1",IF(AND(F21>=7,G21<=12),"Fase 2","Transversal"))) -> Fase 1 | J21: 1.3.1
A22: 1.3.3 | B22: 3 | C22: Biblioteca personal y estados de lectura | D22: Biblioteca con estados de lectura | E22: =MID(IF(RIGHT(RACI!C21,1)="R",", Josyan Bonnemaison","")&IF(RIGHT(RACI!D21,1)="R",", Nicole Marchant","")&IF(RIGHT(RACI!E21,1)="R",", Katherine Rubilar",""),3,200) -> Josyan Bonnemaison, Nicole Marchant | F22: 5 | G22: 5 | H22: =G22-F22+1 -> 1 | I22: =IF(F22>=13,"Fase 3",IF(G22<=6,"Fase 1",IF(AND(F22>=7,G22<=12),"Fase 2","Transversal"))) -> Fase 1 | J22: 1.3.2
A23: 1.3.4 | B23: 3 | C23: Valoraciones, reseñas y emociones | D23: Registro de la experiencia de lectura | E23: =MID(IF(RIGHT(RACI!C22,1)="R",", Josyan Bonnemaison","")&IF(RIGHT(RACI!D22,1)="R",", Nicole Marchant","")&IF(RIGHT(RACI!E22,1)="R",", Katherine Rubilar",""),3,200) -> Josyan Bonnemaison, Nicole Marchant | F23: 6 | G23: 6 | H23: =G23-F23+1 -> 1 | I23: =IF(F23>=13,"Fase 3",IF(G23<=6,"Fase 1",IF(AND(F23>=7,G23<=12),"Fase 2","Transversal"))) -> Fase 1 | J23: 1.3.3
A24: 1.3.5 | B24: 3 | C24: Integración frontend-backend | D24: Aplicación funcionando completa sin IA | E24: =MID(IF(RIGHT(RACI!C23,1)="R",", Josyan Bonnemaison","")&IF(RIGHT(RACI!D23,1)="R",", Nicole Marchant","")&IF(RIGHT(RACI!E23,1)="R",", Katherine Rubilar",""),3,200) -> Josyan Bonnemaison, Nicole Marchant, Katherine Rubilar | F24: 7 | G24: 7 | H24: =G24-F24+1 -> 1 | I24: =IF(F24>=13,"Fase 3",IF(G24<=6,"Fase 1",IF(AND(F24>=7,G24<=12),"Fase 2","Transversal"))) -> Fase 2 | J24: 1.3.1, 1.3.2, 1.3.3, 1.3.4
A25: 1.4 | B25: 2 | C25: Ingeniería de datos (ETL) | F25: =MIN(F26:F29) -> 8 | G25: =MAX(G26:G29) -> 9 | H25: =G25-F25+1 -> 2 | I25: =IF(F25>=13,"Fase 3",IF(G25<=6,"Fase 1",IF(AND(F25>=7,G25<=12),"Fase 2","Transversal"))) -> Fase 2
A26: 1.4.1 | B26: 3 | C26: Extracción de datos operacionales | D26: Scripts de extracción desde PostgreSQL | E26: =MID(IF(RIGHT(RACI!C25,1)="R",", Josyan Bonnemaison","")&IF(RIGHT(RACI!D25,1)="R",", Nicole Marchant","")&IF(RIGHT(RACI!E25,1)="R",", Katherine Rubilar",""),3,200) -> Nicole Marchant | F26: 8 | G26: 8 | H26: =G26-F26+1 -> 1 | I26: =IF(F26>=13,"Fase 3",IF(G26<=6,"Fase 1",IF(AND(F26>=7,G26<=12),"Fase 2","Transversal"))) -> Fase 2 | J26: 1.3.5
A27: 1.4.2 | B27: 3 | C27: Limpieza y normalización | D27: Reglas de limpieza y log de descartes | E27: =MID(IF(RIGHT(RACI!C26,1)="R",", Josyan Bonnemaison","")&IF(RIGHT(RACI!D26,1)="R",", Nicole Marchant","")&IF(RIGHT(RACI!E26,1)="R",", Katherine Rubilar",""),3,200) -> Nicole Marchant | F27: 8 | G27: 8 | H27: =G27-F27+1 -> 1 | I27: =IF(F27>=13,"Fase 3",IF(G27<=6,"Fase 1",IF(AND(F27>=7,G27<=12),"Fase 2","Transversal"))) -> Fase 2 | J27: 1.4.1
A28: 1.4.3 | B28: 3 | C28: Transformación y carga en capa analítica | D28: Capa analítica separada y seudonimizada | E28: =MID(IF(RIGHT(RACI!C27,1)="R",", Josyan Bonnemaison","")&IF(RIGHT(RACI!D27,1)="R",", Nicole Marchant","")&IF(RIGHT(RACI!E27,1)="R",", Katherine Rubilar",""),3,200) -> Nicole Marchant | F28: 8 | G28: 8 | H28: =G28-F28+1 -> 1 | I28: =IF(F28>=13,"Fase 3",IF(G28<=6,"Fase 1",IF(AND(F28>=7,G28<=12),"Fase 2","Transversal"))) -> Fase 2 | J28: 1.4.2
A29: 1.4.4 | B29: 3 | C29: Generación de variables analíticas | D29: Variables de lectura, valoración y emoción | E29: =MID(IF(RIGHT(RACI!C28,1)="R",", Josyan Bonnemaison","")&IF(RIGHT(RACI!D28,1)="R",", Nicole Marchant","")&IF(RIGHT(RACI!E28,1)="R",", Katherine Rubilar",""),3,200) -> Nicole Marchant | F29: 9 | G29: 9 | H29: =G29-F29+1 -> 1 | I29: =IF(F29>=13,"Fase 3",IF(G29<=6,"Fase 1",IF(AND(F29>=7,G29<=12),"Fase 2","Transversal"))) -> Fase 2 | J29: 1.4.3
A30: 1.5 | B30: 2 | C30: Inteligencia artificial | F30: =MIN(F31:F34) -> 10 | G30: =MAX(G31:G34) -> 11 | H30: =G30-F30+1 -> 2 | I30: =IF(F30>=13,"Fase 3",IF(G30<=6,"Fase 1",IF(AND(F30>=7,G30<=12),"Fase 2","Transversal"))) -> Fase 2
A31: 1.5.1 | B31: 3 | C31: Diseño del prompt y restricciones éticas | D31: Prompt documentado, sin lenguaje de diagnóstico | E31: =MID(IF(RIGHT(RACI!C30,1)="R",", Josyan Bonnemaison","")&IF(RIGHT(RACI!D30,1)="R",", Nicole Marchant","")&IF(RIGHT(RACI!E30,1)="R",", Katherine Rubilar",""),3,200) -> Nicole Marchant | F31: 10 | G31: 10 | H31: =G31-F31+1 -> 1 | I31: =IF(F31>=13,"Fase 3",IF(G31<=6,"Fase 1",IF(AND(F31>=7,G31<=12),"Fase 2","Transversal"))) -> Fase 2 | J31: 1.4.4
A32: 1.5.2 | B32: 3 | C32: Servicio de integración con el modelo de lenguaje (Ollama) | D32: Servicio desacoplado con respuesta de respaldo | E32: =MID(IF(RIGHT(RACI!C31,1)="R",", Josyan Bonnemaison","")&IF(RIGHT(RACI!D31,1)="R",", Nicole Marchant","")&IF(RIGHT(RACI!E31,1)="R",", Katherine Rubilar",""),3,200) -> Nicole Marchant | F32: 10 | G32: 10 | H32: =G32-F32+1 -> 1 | I32: =IF(F32>=13,"Fase 3",IF(G32<=6,"Fase 1",IF(AND(F32>=7,G32<=12),"Fase 2","Transversal"))) -> Fase 2 | J32: 1.5.1, 1.4.4
A33: 1.5.3 | B33: 3 | C33: Análisis de perfil lector y recepción de obra | D33: Interpretaciones generadas por la IA | E33: =MID(IF(RIGHT(RACI!C32,1)="R",", Josyan Bonnemaison","")&IF(RIGHT(RACI!D32,1)="R",", Nicole Marchant","")&IF(RIGHT(RACI!E32,1)="R",", Katherine Rubilar",""),3,200) -> Nicole Marchant | F33: 11 | G33: 11 | H33: =G33-F33+1 -> 1 | I33: =IF(F33>=13,"Fase 3",IF(G33<=6,"Fase 1",IF(AND(F33>=7,G33<=12),"Fase 2","Transversal"))) -> Fase 2 | J33: 1.5.2
A34: 1.5.4 | B34: 3 | C34: Visualización de resultados | D34: Vista de resultados en la interfaz | E34: =MID(IF(RIGHT(RACI!C33,1)="R",", Josyan Bonnemaison","")&IF(RIGHT(RACI!D33,1)="R",", Nicole Marchant","")&IF(RIGHT(RACI!E33,1)="R",", Katherine Rubilar",""),3,200) -> Josyan Bonnemaison, Katherine Rubilar | F34: 11 | G34: 11 | H34: =G34-F34+1 -> 1 | I34: =IF(F34>=13,"Fase 3",IF(G34<=6,"Fase 1",IF(AND(F34>=7,G34<=12),"Fase 2","Transversal"))) -> Fase 2 | J34: 1.5.3
A35: 1.6 | B35: 2 | C35: Calidad y cierre | F35: =MIN(F36:F41) -> 2 | G35: =MAX(G36:G41) -> 18 | H35: =G35-F35+1 -> 17 | I35: =IF(F35>=13,"Fase 3",IF(G35<=6,"Fase 1",IF(AND(F35>=7,G35<=12),"Fase 2","Transversal"))) -> Transversal
A36: 1.6.1 | B36: 3 | C36: Pruebas unitarias y de API | D36: Suite pytest y pruebas de endpoints | E36: =MID(IF(RIGHT(RACI!C35,1)="R",", Josyan Bonnemaison","")&IF(RIGHT(RACI!D35,1)="R",", Nicole Marchant","")&IF(RIGHT(RACI!E35,1)="R",", Katherine Rubilar",""),3,200) -> Nicole Marchant, Katherine Rubilar | F36: 3 | G36: 11 | H36: =G36-F36+1 -> 9 | I36: =IF(F36>=13,"Fase 3",IF(G36<=6,"Fase 1",IF(AND(F36>=7,G36<=12),"Fase 2","Transversal"))) -> Transversal | J36: 1.2.6
A37: 1.6.2 | B37: 3 | C37: Pruebas funcionales e integrales | D37: Casos de prueba de Jira (épica EP-17) ejecutados | E37: =MID(IF(RIGHT(RACI!C36,1)="R",", Josyan Bonnemaison","")&IF(RIGHT(RACI!D36,1)="R",", Nicole Marchant","")&IF(RIGHT(RACI!E36,1)="R",", Katherine Rubilar",""),3,200) -> Josyan Bonnemaison, Nicole Marchant, Katherine Rubilar | F37: 12 | G37: 12 | H37: =G37-F37+1 -> 1 | I37: =IF(F37>=13,"Fase 3",IF(G37<=6,"Fase 1",IF(AND(F37>=7,G37<=12),"Fase 2","Transversal"))) -> Fase 2 | J37: 1.5.4
A38: 1.6.3 | B38: 3 | C38: Seguridad y protección de datos | D38: Controles de seguridad definidos en el diseño (S2) y verificados antes del cierre (S12) | E38: =MID(IF(RIGHT(RACI!C37,1)="R",", Josyan Bonnemaison","")&IF(RIGHT(RACI!D37,1)="R",", Nicole Marchant","")&IF(RIGHT(RACI!E37,1)="R",", Katherine Rubilar",""),3,200) -> Nicole Marchant, Katherine Rubilar | F38: 2 | G38: 12 | H38: =G38-F38+1 -> 11 | I38: =IF(F38>=13,"Fase 3",IF(G38<=6,"Fase 1",IF(AND(F38>=7,G38<=12),"Fase 2","Transversal"))) -> Transversal | J38: 1.2.3
A39: 1.6.4 | B39: 3 | C39: Documentación técnica | D39: README, guía Docker y documentación del ETL | E39: =MID(IF(RIGHT(RACI!C38,1)="R",", Josyan Bonnemaison","")&IF(RIGHT(RACI!D38,1)="R",", Nicole Marchant","")&IF(RIGHT(RACI!E38,1)="R",", Katherine Rubilar",""),3,200) -> Nicole Marchant, Katherine Rubilar | F39: 12 | G39: 12 | H39: =G39-F39+1 -> 1 | I39: =IF(F39>=13,"Fase 3",IF(G39<=6,"Fase 1",IF(AND(F39>=7,G39<=12),"Fase 2","Transversal"))) -> Fase 2 | J39: 1.5.4
A40: 1.6.5 | B40: 3 | C40: Ajustes críticos y consolidación de evidencias | D40: Evidencias finales del MVP | E40: =MID(IF(RIGHT(RACI!C39,1)="R",", Josyan Bonnemaison","")&IF(RIGHT(RACI!D39,1)="R",", Nicole Marchant","")&IF(RIGHT(RACI!E39,1)="R",", Katherine Rubilar",""),3,200) -> Josyan Bonnemaison, Nicole Marchant | F40: 13 | G40: 15 | H40: =G40-F40+1 -> 3 | I40: =IF(F40>=13,"Fase 3",IF(G40<=6,"Fase 1",IF(AND(F40>=7,G40<=12),"Fase 2","Transversal"))) -> Fase 3 | J40: 1.6.2, 1.6.3, 1.6.4
A41: 1.6.6 | B41: 3 | C41: Informe y presentación final | D41: Informe final y demostración | E41: =MID(IF(RIGHT(RACI!C40,1)="R",", Josyan Bonnemaison","")&IF(RIGHT(RACI!D40,1)="R",", Nicole Marchant","")&IF(RIGHT(RACI!E40,1)="R",", Katherine Rubilar",""),3,200) -> Josyan Bonnemaison, Nicole Marchant, Katherine Rubilar | F41: 16 | G41: 18 | H41: =G41-F41+1 -> 3 | I41: =IF(F41>=13,"Fase 3",IF(G41<=6,"Fase 1",IF(AND(F41>=7,G41<=12),"Fase 2","Transversal"))) -> Fase 3 | J41: 1.6.5

Sheet Diagrama EDT
A1: Diagrama EDT
A2: Versión gráfica de la hoja EDT.

Sheet Roles
A1: Roles y responsabilidades
A4: Rol | B4: Integrante | C4: Responsabilidades | D4: Paquetes donde aprueba (A) | E4: Paquetes donde ejecuta (R)
A5: Frontend / UX-UI | B5: Josyan Bonnemaison | C5: Diseña y construye la interfaz en React, implementa la experiencia de usuario, participa en la integración frontend-backend, visualiza resultados y lidera las pruebas funcionales y la presentación. | D5: =COUNTIF(RACI!C:C,"A*") -> 9 | E5: =COUNTIF(RACI!C:C,"*R") -> 11
A6: Backend / Base de Datos, Integraciones, ETL e IA | B6: Nicole Marchant | C6: Implementa la API en FastAPI, el modelo de datos en PostgreSQL, autenticación, catálogo e integraciones; desde la Fase 2 desarrolla el ETL, las variables analíticas y la integración con IA (Ollama); participa en seguridad, contratos de API y pruebas técnicas. | D6: =COUNTIF(RACI!D:D,"A*") -> 11 | E6: =COUNTIF(RACI!D:D,"*R") -> 22
A7: Coordinación de Proyecto / Frontend | B7: Katherine Rubilar | C7: Coordina alcance, planificación, riesgos y seguimiento; aprueba los entregables de ETL e IA y, desde la Fase 2, apoya el desarrollo de las vistas del frontend. | D7: =COUNTIF(RACI!E:E,"A*") -> 10 | E7: =COUNTIF(RACI!E:E,"*R") -> 13

Sheet RACI
A1: Matriz RACI
A2: R = ejecuta · A = aprueba y rinde cuentas · A/R = dueño que ejecuta y responde · C = es consultado · I = es informado.
A4: Código EDT | B4: Paquete / entregable | C4: Josyan Bonnemaison (Frontend / UX-UI) | D4: Nicole Marchant (Backend / BD / ETL / IA) | E4: Katherine Rubilar (Coordinación / Frontend) | F4: Docente guía | G4: Control
A5: 1.1 | B5: =EDT!C6 -> Gestión del proyecto
A6: 1.1.1 | B6: =EDT!C7 -> Definición de alcance y backlog del MVP | C6: C | D6: A | E6: R | F6: C | G6: =IF(AND(COUNTIF(C6:F6,"A*")=1,COUNTIF(C6:F6,"*R")>=1,OR(LEFT(A6,4)<>"1.1.",COUNTIF(C6:F6,"A/R")=0)),"OK","Revisar: 1 A, al menos 1 R; en Gestión, A y R separados") -> OK
A7: 1.1.2 | B7: =EDT!C8 -> Plan de trabajo y carta Gantt | C7: A | D7: C | E7: R | F7: I | G7: =IF(AND(COUNTIF(C7:F7,"A*")=1,COUNTIF(C7:F7,"*R")>=1,OR(LEFT(A7,4)<>"1.1.",COUNTIF(C7:F7,"A/R")=0)),"OK","Revisar: 1 A, al menos 1 R; en Gestión, A y R separados") -> OK
A8: 1.1.3 | B8: =EDT!C9 -> Asignación de roles y responsabilidades | C8: A | D8: C | E8: R | F8: I | G8: =IF(AND(COUNTIF(C8:F8,"A*")=1,COUNTIF(C8:F8,"*R")>=1,OR(LEFT(A8,4)<>"1.1.",COUNTIF(C8:F8,"A/R")=0)),"OK","Revisar: 1 A, al menos 1 R; en Gestión, A y R separados") -> OK
A9: 1.1.4 | B9: =EDT!C10 -> Gestión de riesgos | C9: C | D9: A | E9: R | F9: I | G9: =IF(AND(COUNTIF(C9:F9,"A*")=1,COUNTIF(C9:F9,"*R")>=1,OR(LEFT(A9,4)<>"1.1.",COUNTIF(C9:F9,"A/R")=0)),"OK","Revisar: 1 A, al menos 1 R; en Gestión, A y R separados") -> OK
A10: 1.1.5 | B10: =EDT!C11 -> Seguimiento y control del avance | C10: A | D10: C | E10: R | F10: I | G10: =IF(AND(COUNTIF(C10:F10,"A*")=1,COUNTIF(C10:F10,"*R")>=1,OR(LEFT(A10,4)<>"1.1.",COUNTIF(C10:F10,"A/R")=0)),"OK","Revisar: 1 A, al menos 1 R; en Gestión, A y R separados") -> OK
A11: 1.2 | B11: =EDT!C12 -> Análisis y diseño
A12: 1.2.1 | B12: =EDT!C13 -> Requerimientos e historias de usuario | C12: C | D12: R | E12: A/R | F12: C | G12: =IF(AND(COUNTIF(C12:F12,"A*")=1,COUNTIF(C12:F12,"*R")>=1,OR(LEFT(A12,4)<>"1.1.",COUNTIF(C12:F12,"A/R")=0)),"OK","Revisar: 1 A, al menos 1 R; en Gestión, A y R separados") -> OK
A13: 1.2.2 | B13: =EDT!C14 -> Modelado de procesos (BPMN) y casos de uso | C13: A/R | D13: C | E13: C | F13: C | G13: =IF(AND(COUNTIF(C13:F13,"A*")=1,COUNTIF(C13:F13,"*R")>=1,OR(LEFT(A13,4)<>"1.1.",COUNTIF(C13:F13,"A/R")=0)),"OK","Revisar: 1 A, al menos 1 R; en Gestión, A y R separados") -> OK
A14: 1.2.3 | B14: =EDT!C15 -> Arquitectura del sistema | C14: C | D14: A/R | E14: C | F14: C | G14: =IF(AND(COUNTIF(C14:F14,"A*")=1,COUNTIF(C14:F14,"*R")>=1,OR(LEFT(A14,4)<>"1.1.",COUNTIF(C14:F14,"A/R")=0)),"OK","Revisar: 1 A, al menos 1 R; en Gestión, A y R separados") -> OK
A15: 1.2.4 | B15: =EDT!C16 -> Modelo de datos operacional y analítico | C15: I | D15: A/R | E15: C | F15: C | G15: =IF(AND(COUNTIF(C15:F15,"A*")=1,COUNTIF(C15:F15,"*R")>=1,OR(LEFT(A15,4)<>"1.1.",COUNTIF(C15:F15,"A/R")=0)),"OK","Revisar: 1 A, al menos 1 R; en Gestión, A y R separados") -> OK
A16: 1.2.5 | B16: =EDT!C17 -> Diseño UI/UX y mockups | C16: A/R | D16: C | E16: C | F16: I | G16: =IF(AND(COUNTIF(C16:F16,"A*")=1,COUNTIF(C16:F16,"*R")>=1,OR(LEFT(A16,4)<>"1.1.",COUNTIF(C16:F16,"A/R")=0)),"OK","Revisar: 1 A, al menos 1 R; en Gestión, A y R separados") -> OK
A17: 1.2.6 | B17: =EDT!C18 -> Contratos de API | C17: C | D17: A/R | E17: C | F17: I | G17: =IF(AND(COUNTIF(C17:F17,"A*")=1,COUNTIF(C17:F17,"*R")>=1,OR(LEFT(A17,4)<>"1.1.",COUNTIF(C17:F17,"A/R")=0)),"OK","Revisar: 1 A, al menos 1 R; en Gestión, A y R separados") -> OK
A18: 1.3 | B18: =EDT!C19 -> Desarrollo de la aplicación web
A19: 1.3.1 | B19: =EDT!C20 -> Autenticación, usuarios y perfil lector | C19: R | D19: A/R | E19: I | F19: I | G19: =IF(AND(COUNTIF(C19:F19,"A*")=1,COUNTIF(C19:F19,"*R")>=1,OR(LEFT(A19,4)<>"1.1.",COUNTIF(C19:F19,"A/R")=0)),"OK","Revisar: 1 A, al menos 1 R; en Gestión, A y R separados") -> OK
A20: 1.3.2 | B20: =EDT!C21 -> Catálogo y búsqueda de libros | C20: R | D20: A/R | E20: I | F20: I | G20: =IF(AND(COUNTIF(C20:F20,"A*")=1,COUNTIF(C20:F20,"*R")>=1,OR(LEFT(A20,4)<>"1.1.",COUNTIF(C20:F20,"A/R")=0)),"OK","Revisar: 1 A, al menos 1 R; en Gestión, A y R separados") -> OK
A21: 1.3.3 | B21: =EDT!C22 -> Biblioteca personal y estados de lectura | C21: R | D21: A/R | E21: I | F21: I | G21: =IF(AND(COUNTIF(C21:F21,"A*")=1,COUNTIF(C21:F21,"*R")>=1,OR(LEFT(A21,4)<>"1.1.",COUNTIF(C21:F21,"A/R")=0)),"OK","Revisar: 1 A, al menos 1 R; en Gestión, A y R separados") -> OK
A22: 1.3.4 | B22: =EDT!C23 -> Valoraciones, reseñas y emociones | C22: R | D22: A/R | E22: C | F22: C | G22: =IF(AND(COUNTIF(C22:F22,"A*")=1,COUNTIF(C22:F22,"*R")>=1,OR(LEFT(A22,4)<>"1.1.",COUNTIF(C22:F22,"A/R")=0)),"OK","Revisar: 1 A, al menos 1 R; en Gestión, A y R separados") -> OK
A23: 1.3.5 | B23: =EDT!C24 -> Integración frontend-backend | C23: A/R | D23: R | E23: R | F23: I | G23: =IF(AND(COUNTIF(C23:F23,"A*")=1,COUNTIF(C23:F23,"*R")>=1,OR(LEFT(A23,4)<>"1.1.",COUNTIF(C23:F23,"A/R")=0)),"OK","Revisar: 1 A, al menos 1 R; en Gestión, A y R separados") -> OK
A24: 1.4 | B24: =EDT!C25 -> Ingeniería de datos (ETL)
A25: 1.4.1 | B25: =EDT!C26 -> Extracción de datos operacionales | C25: I | D25: R | E25: A | F25: I | G25: =IF(AND(COUNTIF(C25:F25,"A*")=1,COUNTIF(C25:F25,"*R")>=1,OR(LEFT(A25,4)<>"1.1.",COUNTIF(C25:F25,"A/R")=0)),"OK","Revisar: 1 A, al menos 1 R; en Gestión, A y R separados") -> OK
A26: 1.4.2 | B26: =EDT!C27 -> Limpieza y normalización | C26: I | D26: R | E26: A | F26: I | G26: =IF(AND(COUNTIF(C26:F26,"A*")=1,COUNTIF(C26:F26,"*R")>=1,OR(LEFT(A26,4)<>"1.1.",COUNTIF(C26:F26,"A/R")=0)),"OK","Revisar: 1 A, al menos 1 R; en Gestión, A y R separados") -> OK
A27: 1.4.3 | B27: =EDT!C28 -> Transformación y carga en capa analítica | C27: I | D27: R | E27: A | F27: I | G27: =IF(AND(COUNTIF(C27:F27,"A*")=1,COUNTIF(C27:F27,"*R")>=1,OR(LEFT(A27,4)<>"1.1.",COUNTIF(C27:F27,"A/R")=0)),"OK","Revisar: 1 A, al menos 1 R; en Gestión, A y R separados") -> OK
A28: 1.4.4 | B28: =EDT!C29 -> Generación de variables analíticas | C28: C | D28: R | E28: A | F28: I | G28: =IF(AND(COUNTIF(C28:F28,"A*")=1,COUNTIF(C28:F28,"*R")>=1,OR(LEFT(A28,4)<>"1.1.",COUNTIF(C28:F28,"A/R")=0)),"OK","Revisar: 1 A, al menos 1 R; en Gestión, A y R separados") -> OK
A29: 1.5 | B29: =EDT!C30 -> Inteligencia artificial
A30: 1.5.1 | B30: =EDT!C31 -> Diseño del prompt y restricciones éticas | C30: C | D30: R | E30: A | F30: C | G30: =IF(AND(COUNTIF(C30:F30,"A*")=1,COUNTIF(C30:F30,"*R")>=1,OR(LEFT(A30,4)<>"1.1.",COUNTIF(C30:F30,"A/R")=0)),"OK","Revisar: 1 A, al menos 1 R; en Gestión, A y R separados") -> OK
A31: 1.5.2 | B31: =EDT!C32 -> Servicio de integración con el modelo de lenguaje (Ollama) | C31: C | D31: R | E31: A | F31: I | G31: =IF(AND(COUNTIF(C31:F31,"A*")=1,COUNTIF(C31:F31,"*R")>=1,OR(LEFT(A31,4)<>"1.1.",COUNTIF(C31:F31,"A/R")=0)),"OK","Revisar: 1 A, al menos 1 R; en Gestión, A y R separados") -> OK
A32: 1.5.3 | B32: =EDT!C33 -> Análisis de perfil lector y recepción de obra | C32: C | D32: R | E32: A | F32: I | G32: =IF(AND(COUNTIF(C32:F32,"A*")=1,COUNTIF(C32:F32,"*R")>=1,OR(LEFT(A32,4)<>"1.1.",COUNTIF(C32:F32,"A/R")=0)),"OK","Revisar: 1 A, al menos 1 R; en Gestión, A y R separados") -> OK
A33: 1.5.4 | B33: =EDT!C34 -> Visualización de resultados | C33: A/R | D33: C | E33: R | F33: I | G33: =IF(AND(COUNTIF(C33:F33,"A*")=1,COUNTIF(C33:F33,"*R")>=1,OR(LEFT(A33,4)<>"1.1.",COUNTIF(C33:F33,"A/R")=0)),"OK","Revisar: 1 A, al menos 1 R; en Gestión, A y R separados") -> OK
A34: 1.6 | B34: =EDT!C35 -> Calidad y cierre
A35: 1.6.1 | B35: =EDT!C36 -> Pruebas unitarias y de API | C35: I | D35: A/R | E35: R | F35: I | G35: =IF(AND(COUNTIF(C35:F35,"A*")=1,COUNTIF(C35:F35,"*R")>=1,OR(LEFT(A35,4)<>"1.1.",COUNTIF(C35:F35,"A/R")=0)),"OK","Revisar: 1 A, al menos 1 R; en Gestión, A y R separados") -> OK
A36: 1.6.2 | B36: =EDT!C37 -> Pruebas funcionales e integrales | C36: A/R | D36: R | E36: R | F36: I | G36: =IF(AND(COUNTIF(C36:F36,"A*")=1,COUNTIF(C36:F36,"*R")>=1,OR(LEFT(A36,4)<>"1.1.",COUNTIF(C36:F36,"A/R")=0)),"OK","Revisar: 1 A, al menos 1 R; en Gestión, A y R separados") -> OK
A37: 1.6.3 | B37: =EDT!C38 -> Seguridad y protección de datos | C37: C | D37: A/R | E37: R | F37: I | G37: =IF(AND(COUNTIF(C37:F37,"A*")=1,COUNTIF(C37:F37,"*R")>=1,OR(LEFT(A37,4)<>"1.1.",COUNTIF(C37:F37,"A/R")=0)),"OK","Revisar: 1 A, al menos 1 R; en Gestión, A y R separados") -> OK
A38: 1.6.4 | B38: =EDT!C39 -> Documentación técnica | C38: A | D38: R | E38: R | F38: I | G38: =IF(AND(COUNTIF(C38:F38,"A*")=1,COUNTIF(C38:F38,"*R")>=1,OR(LEFT(A38,4)<>"1.1.",COUNTIF(C38:F38,"A/R")=0)),"OK","Revisar: 1 A, al menos 1 R; en Gestión, A y R separados") -> OK
A39: 1.6.5 | B39: =EDT!C40 -> Ajustes críticos y consolidación de evidencias | C39: R | D39: R | E39: A | F39: I | G39: =IF(AND(COUNTIF(C39:F39,"A*")=1,COUNTIF(C39:F39,"*R")>=1,OR(LEFT(A39,4)<>"1.1.",COUNTIF(C39:F39,"A/R")=0)),"OK","Revisar: 1 A, al menos 1 R; en Gestión, A y R separados") -> OK
A40: 1.6.6 | B40: =EDT!C41 -> Informe y presentación final | C40: R | D40: R | E40: A/R | F40: C | G40: =IF(AND(COUNTIF(C40:F40,"A*")=1,COUNTIF(C40:F40,"*R")>=1,OR(LEFT(A40,4)<>"1.1.",COUNTIF(C40:F40,"A/R")=0)),"OK","Revisar: 1 A, al menos 1 R; en Gestión, A y R separados") -> OK

Sheet Gantt
A1: Carta Gantt — 18 semanas
F3: Fase 1 | L3: Fase 2 | R3: Fase 3
A4: Código | B4: Paquete / entregable | C4: Responsable(s) (R) | D4: Inicio | E4: Fin | F4: 1 | G4: 2 | H4: 3 | I4: 4 | J4: 5 | K4: 6 | L4: 7 | M4: 8 | N4: 9 | O4: 10 | P4: 11 | Q4: 12 | R4: 13 | S4: 14 | T4: 15 | U4: 16 | V4: 17 | W4: 18 | X4: Predecesora(s)
A5: 1.1 | B5: =EDT!C6 -> Gestión del proyecto | D5: =EDT!F6 -> 1 | E5: =EDT!G6 -> 18 | X5: =IF(EDT!J6="","",EDT!J6)
A6: 1.1.1 | B6: =EDT!C7 -> Definición de alcance y backlog del MVP | C6: =IF(EDT!E7=0,"",EDT!E7) -> Katherine Rubilar | D6: =EDT!F7 -> 1 | E6: =EDT!G7 -> 1 | X6: =IF(EDT!J7="","",EDT!J7)
A7: 1.1.2 | B7: =EDT!C8 -> Plan de trabajo y carta Gantt | C7: =IF(EDT!E8=0,"",EDT!E8) -> Katherine Rubilar | D7: =EDT!F8 -> 1 | E7: =EDT!G8 -> 1 | X7: =IF(EDT!J8="","",EDT!J8) -> 1.1.1
A8: 1.1.3 | B8: =EDT!C9 -> Asignación de roles y responsabilidades | C8: =IF(EDT!E9=0,"",EDT!E9) -> Katherine Rubilar | D8: =EDT!F9 -> 1 | E8: =EDT!G9 -> 1 | X8: =IF(EDT!J9="","",EDT!J9) -> 1.1.1
A9: 1.1.4 | B9: =EDT!C10 -> Gestión de riesgos | C9: =IF(EDT!E10=0,"",EDT!E10) -> Katherine Rubilar | D9: =EDT!F10 -> 1 | E9: =EDT!G10 -> 18 | X9: =IF(EDT!J10="","",EDT!J10) -> 1.1.1
A10: 1.1.5 | B10: =EDT!C11 -> Seguimiento y control del avance | C10: =IF(EDT!E11=0,"",EDT!E11) -> Katherine Rubilar | D10: =EDT!F11 -> 2 | E10: =EDT!G11 -> 18 | X10: =IF(EDT!J11="","",EDT!J11) -> 1.1.2
A11: 1.2 | B11: =EDT!C12 -> Análisis y diseño | D11: =EDT!F12 -> 1 | E11: =EDT!G12 -> 2 | X11: =IF(EDT!J12="","",EDT!J12)
A12: 1.2.1 | B12: =EDT!C13 -> Requerimientos e historias de usuario | C12: =IF(EDT!E13=0,"",EDT!E13) -> Nicole Marchant, Katherine Rubilar | D12: =EDT!F13 -> 1 | E12: =EDT!G13 -> 1 | X12: =IF(EDT!J13="","",EDT!J13) -> 1.1.1
A13: 1.2.2 | B13: =EDT!C14 -> Modelado de procesos (BPMN) y casos de uso | C13: =IF(EDT!E14=0,"",EDT!E14) -> Josyan Bonnemaison | D13: =EDT!F14 -> 1 | E13: =EDT!G14 -> 1 | X13: =IF(EDT!J14="","",EDT!J14) -> 1.2.1
A14: 1.2.3 | B14: =EDT!C15 -> Arquitectura del sistema | C14: =IF(EDT!E15=0,"",EDT!E15) -> Nicole Marchant | D14: =EDT!F15 -> 1 | E14: =EDT!G15 -> 1 | X14: =IF(EDT!J15="","",EDT!J15) -> 1.2.1
A15: 1.2.4 | B15: =EDT!C16 -> Modelo de datos operacional y analítico | C15: =IF(EDT!E16=0,"",EDT!E16) -> Nicole Marchant | D15: =EDT!F16 -> 2 | E15: =EDT!G16 -> 2 | X15: =IF(EDT!J16="","",EDT!J16) -> 1.2.3
A16: 1.2.5 | B16: =EDT!C17 -> Diseño UI/UX y mockups | C16: =IF(EDT!E17=0,"",EDT!E17) -> Josyan Bonnemaison | D16: =EDT!F17 -> 2 | E16: =EDT!G17 -> 2 | X16: =IF(EDT!J17="","",EDT!J17) -> 1.2.1
A17: 1.2.6 | B17: =EDT!C18 -> Contratos de API | C17: =IF(EDT!E18=0,"",EDT!E18) -> Nicole Marchant | D17: =EDT!F18 -> 2 | E17: =EDT!G18 -> 2 | X17: =IF(EDT!J18="","",EDT!J18) -> 1.2.3, 1.2.4
A18: 1.3 | B18: =EDT!C19 -> Desarrollo de la aplicación web | D18: =EDT!F19 -> 3 | E18: =EDT!G19 -> 7 | X18: =IF(EDT!J19="","",EDT!J19)
A19: 1.3.1 | B19: =EDT!C20 -> Autenticación, usuarios y perfil lector | C19: =IF(EDT!E20=0,"",EDT!E20) -> Josyan Bonnemaison, Nicole Marchant | D19: =EDT!F20 -> 3 | E19: =EDT!G20 -> 3 | X19: =IF(EDT!J20="","",EDT!J20) -> 1.2.3, 1.2.5, 1.2.6
A20: 1.3.2 | B20: =EDT!C21 -> Catálogo y búsqueda de libros | C20: =IF(EDT!E21=0,"",EDT!E21) -> Josyan Bonnemaison, Nicole Marchant | D20: =EDT!F21 -> 4 | E20: =EDT!G21 -> 4 | X20: =IF(EDT!J21="","",EDT!J21) -> 1.3.1
A21: 1.3.3 | B21: =EDT!C22 -> Biblioteca personal y estados de lectura | C21: =IF(EDT!E22=0,"",EDT!E22) -> Josyan Bonnemaison, Nicole Marchant | D21: =EDT!F22 -> 5 | E21: =EDT!G22 -> 5 | X21: =IF(EDT!J22="","",EDT!J22) -> 1.3.2
A22: 1.3.4 | B22: =EDT!C23 -> Valoraciones, reseñas y emociones | C22: =IF(EDT!E23=0,"",EDT!E23) -> Josyan Bonnemaison, Nicole Marchant | D22: =EDT!F23 -> 6 | E22: =EDT!G23 -> 6 | X22: =IF(EDT!J23="","",EDT!J23) -> 1.3.3
A23: 1.3.5 | B23: =EDT!C24 -> Integración frontend-backend | C23: =IF(EDT!E24=0,"",EDT!E24) -> Josyan Bonnemaison, Nicole Marchant, Katherine Rubilar | D23: =EDT!F24 -> 7 | E23: =EDT!G24 -> 7 | X23: =IF(EDT!J24="","",EDT!J24) -> 1.3.1, 1.3.2, 1.3.3, 1.3.4
A24: 1.4 | B24: =EDT!C25 -> Ingeniería de datos (ETL) | D24: =EDT!F25 -> 8 | E24: =EDT!G25 -> 9 | X24: =IF(EDT!J25="","",EDT!J25)
A25: 1.4.1 | B25: =EDT!C26 -> Extracción de datos operacionales | C25: =IF(EDT!E26=0,"",EDT!E26) -> Nicole Marchant | D25: =EDT!F26 -> 8 | E25: =EDT!G26 -> 8 | X25: =IF(EDT!J26="","",EDT!J26) -> 1.3.5
A26: 1.4.2 | B26: =EDT!C27 -> Limpieza y normalización | C26: =IF(EDT!E27=0,"",EDT!E27) -> Nicole Marchant | D26: =EDT!F27 -> 8 | E26: =EDT!G27 -> 8 | X26: =IF(EDT!J27="","",EDT!J27) -> 1.4.1
A27: 1.4.3 | B27: =EDT!C28 -> Transformación y carga en capa analítica | C27: =IF(EDT!E28=0,"",EDT!E28) -> Nicole Marchant | D27: =EDT!F28 -> 8 | E27: =EDT!G28 -> 8 | X27: =IF(EDT!J28="","",EDT!J28) -> 1.4.2
A28: 1.4.4 | B28: =EDT!C29 -> Generación de variables analíticas | C28: =IF(EDT!E29=0,"",EDT!E29) -> Nicole Marchant | D28: =EDT!F29 -> 9 | E28: =EDT!G29 -> 9 | X28: =IF(EDT!J29="","",EDT!J29) -> 1.4.3
A29: 1.5 | B29: =EDT!C30 -> Inteligencia artificial | D29: =EDT!F30 -> 10 | E29: =EDT!G30 -> 11 | X29: =IF(EDT!J30="","",EDT!J30)
A30: 1.5.1 | B30: =EDT!C31 -> Diseño del prompt y restricciones éticas | C30: =IF(EDT!E31=0,"",EDT!E31) -> Nicole Marchant | D30: =EDT!F31 -> 10 | E30: =EDT!G31 -> 10 | X30: =IF(EDT!J31="","",EDT!J31) -> 1.4.4
A31: 1.5.2 | B31: =EDT!C32 -> Servicio de integración con el modelo de lenguaje (Ollama) | C31: =IF(EDT!E32=0,"",EDT!E32) -> Nicole Marchant | D31: =EDT!F32 -> 10 | E31: =EDT!G32 -> 10 | X31: =IF(EDT!J32="","",EDT!J32) -> 1.5.1, 1.4.4
A32: 1.5.3 | B32: =EDT!C33 -> Análisis de perfil lector y recepción de obra | C32: =IF(EDT!E33=0,"",EDT!E33) -> Nicole Marchant | D32: =EDT!F33 -> 11 | E32: =EDT!G33 -> 11 | X32: =IF(EDT!J33="","",EDT!J33) -> 1.5.2
A33: 1.5.4 | B33: =EDT!C34 -> Visualización de resultados | C33: =IF(EDT!E34=0,"",EDT!E34) -> Josyan Bonnemaison, Katherine Rubilar | D33: =EDT!F34 -> 11 | E33: =EDT!G34 -> 11 | X33: =IF(EDT!J34="","",EDT!J34) -> 1.5.3
A34: 1.6 | B34: =EDT!C35 -> Calidad y cierre | D34: =EDT!F35 -> 2 | E34: =EDT!G35 -> 18 | X34: =IF(EDT!J35="","",EDT!J35)
A35: 1.6.1 | B35: =EDT!C36 -> Pruebas unitarias y de API | C35: =IF(EDT!E36=0,"",EDT!E36) -> Nicole Marchant, Katherine Rubilar | D35: =EDT!F36 -> 3 | E35: =EDT!G36 -> 11 | X35: =IF(EDT!J36="","",EDT!J36) -> 1.2.6
A36: 1.6.2 | B36: =EDT!C37 -> Pruebas funcionales e integrales | C36: =IF(EDT!E37=0,"",EDT!E37) -> Josyan Bonnemaison, Nicole Marchant, Katherine Rubilar | D36: =EDT!F37 -> 12 | E36: =EDT!G37 -> 12 | X36: =IF(EDT!J37="","",EDT!J37) -> 1.5.4
A37: 1.6.3 | B37: =EDT!C38 -> Seguridad y protección de datos | C37: =IF(EDT!E38=0,"",EDT!E38) -> Nicole Marchant, Katherine Rubilar | D37: =EDT!F38 -> 2 | E37: =EDT!G38 -> 12 | X37: =IF(EDT!J38="","",EDT!J38) -> 1.2.3
A38: 1.6.4 | B38: =EDT!C39 -> Documentación técnica | C38: =IF(EDT!E39=0,"",EDT!E39) -> Nicole Marchant, Katherine Rubilar | D38: =EDT!F39 -> 12 | E38: =EDT!G39 -> 12 | X38: =IF(EDT!J39="","",EDT!J39) -> 1.5.4
A39: 1.6.5 | B39: =EDT!C40 -> Ajustes críticos y consolidación de evidencias | C39: =IF(EDT!E40=0,"",EDT!E40) -> Josyan Bonnemaison, Nicole Marchant | D39: =EDT!F40 -> 13 | E39: =EDT!G40 -> 15 | X39: =IF(EDT!J40="","",EDT!J40) -> 1.6.2, 1.6.3, 1.6.4
A40: 1.6.6 | B40: =EDT!C41 -> Informe y presentación final | C40: =IF(EDT!E41=0,"",EDT!E41) -> Josyan Bonnemaison, Nicole Marchant, Katherine Rubilar | D40: =EDT!F41 -> 16 | E40: =EDT!G41 -> 18 | X40: =IF(EDT!J41="","",EDT!J41) -> 1.6.5

Sheet Criterios de riesgo
A1: Criterios de evaluación de riesgos
A2: Puntuación = Impacto × Probabilidad (escala 1–5 cada uno; máximo 25)
A4: Nivel | B4: Probabilidad | C4: Descripción
A5: 5 | B5: Muy alta | C5: Más de 70%: casi seguro que ocurra durante el proyecto
A6: 4 | B6: Alta | C6: 50–70%: es más probable que ocurra que no
A7: 3 | B7: Media | C7: 30–50%: puede ocurrir en algún momento
A8: 2 | B8: Baja | C8: 10–30%: poco probable
A9: 1 | B9: Muy baja | C9: Menos de 10%: ocurriría solo en casos excepcionales
A11: Nivel | B11: Impacto | C11: Efecto sobre el MVP
A12: 5 | B12: Muy grave | C12: Impide la demostración del flujo completo o compromete datos personales
A13: 4 | B13: Grave | C13: Atrasa una fase completa o deja fuera un componente del MVP (ETL, IA o app)
A14: 3 | B14: Moderado | C14: Atrasa un módulo 1–2 semanas o baja la calidad de un entregable
A15: 2 | B15: Menor | C15: Retrabajo de pocos días, absorbible dentro de la iteración
A16: 1 | B16: Insignificante | C16: Efecto mínimo, sin cambios en plazo ni alcance
A18: Puntuación mínima | B18: Clasificación | C18: Respuesta esperada
A19: 15 | B19: Extrema | C19: Respuesta inmediata; se revisa en cada reunión semanal
A20: 10 | B20: Alta | C20: Plan de respuesta activo y responsable asignado
A21: 5 | B21: Media | C21: Se monitorea en cada cierre de fase
A22: 1 | B22: Baja | C22: Se acepta y se registra
A24: Estrategia | B24: Tipo | C24: Cuándo se usa
A25: Evitar | B25: Amenaza | C25: Se cambia el plan para eliminar la causa del riesgo
A26: Mitigar | B26: Amenaza | C26: Se reduce la probabilidad o el impacto
A27: Transferir | B27: Amenaza | C27: Se traslada el efecto a un tercero, por ejemplo un proveedor
A28: Aceptar | B28: Amenaza | C28: Se asume el riesgo y se prepara un plan de contingencia

Sheet Registro de riesgos
A1: Registro de riesgos
A2: Ordenado por categoría RBS.
A4: ID | B4: Código EDT | C4: Paquete EDT | D4: Riesgo (causa → efecto) | E4: Categoría | F4: Subcategoría | G4: Impacto (1–5) | H4: Probabilidad (1–5) | I4: Puntuación | J4: Clasificación | K4: Estrategia | L4: Acciones de respuesta | M4: Disparador | N4: Responsable | O4: Fase de ocurrencia | P4: Estado | Q4: Fecha objetivo de respuesta | R4: Última revisión
A5: R-01 | B5: 1.2.1 | C5: {=IFERROR(INDEX(EDT!$C:$C,MATCH(B5,EDT!$A:$A,0)),"Código no existe")} -> Requerimientos e historias de usuario | D5: Requerimientos o historias de usuario ambiguos generan funcionalidades que no calzan con el flujo de la demostración final. | E5: Técnicos | F5: Requisitos | G5: 4 | H5: 3 | I5: =IF(OR(G5="",H5=""),"",G5*H5) -> 12 | J5: =IF(I5="","",IF(I5>='Criterios de riesgo'!$A$19,'Criterios de riesgo'!$B$19,IF(I5>='Criterios de riesgo'!$A$20,'Criterios de riesgo'!$B$20,IF(I5>='Criterios de riesgo'!$A$21,'Criterios de riesgo'!$B$21,'Criterios de riesgo'!$B$22)))) -> Alta | K5: Mitigar | L5: M1: Redactar criterios de aceptación Dado/Cuando/Entonces por historia. M2: Validar el backlog con el docente guía antes de S3. | M5: Historias sin criterios de aceptación o dudas recurrentes al desarrollar | N5: Nicole Marchant | O5: Fase 1 | P5: Abierto
A6: R-02 | B6: 1.2.4 | C6: {=IFERROR(INDEX(EDT!$C:$C,MATCH(B6,EDT!$A:$A,0)),"Código no existe")} -> Modelo de datos operacional y analítico | D6: Un modelo de datos que no separa bien la capa operacional de la analítica obliga a rehacer tablas y el ETL. | E6: Técnicos | F6: Tecnología | G6: 4 | H6: 3 | I6: =IF(OR(G6="",H6=""),"",G6*H6) -> 12 | J6: =IF(I6="","",IF(I6>='Criterios de riesgo'!$A$19,'Criterios de riesgo'!$B$19,IF(I6>='Criterios de riesgo'!$A$20,'Criterios de riesgo'!$B$20,IF(I6>='Criterios de riesgo'!$A$21,'Criterios de riesgo'!$B$21,'Criterios de riesgo'!$B$22)))) -> Alta | K6: Mitigar | L6: M1: Revisar el modelo ER en equipo antes de implementar. M2: Definir desde S2 qué variables necesitará el ETL. | M6: Cambios de esquema después de S4 | N6: Nicole Marchant | O6: Fase 1 | P6: Abierto
A7: R-03 | B7: 1.3.5 | C7: {=IFERROR(INDEX(EDT!$C:$C,MATCH(B7,EDT!$A:$A,0)),"Código no existe")} -> Integración frontend-backend | D7: Errores de integración entre frontend, API y base de datos retrasan el flujo funcional completo. | E7: Técnicos | F7: Interfaces | G7: 4 | H7: 3 | I7: =IF(OR(G7="",H7=""),"",G7*H7) -> 12 | J7: =IF(I7="","",IF(I7>='Criterios de riesgo'!$A$19,'Criterios de riesgo'!$B$19,IF(I7>='Criterios de riesgo'!$A$20,'Criterios de riesgo'!$B$20,IF(I7>='Criterios de riesgo'!$A$21,'Criterios de riesgo'!$B$21,'Criterios de riesgo'!$B$22)))) -> Alta | K7: Mitigar | L7: M1: Contratos de API definidos en S2 y datos mock en el frontend. M2: Integrar por módulo, no al final. | M7: Endpoints que no responden según el contrato | N7: Josyan Bonnemaison | O7: Fase 2 | P7: Abierto
A8: R-04 | B8: 1.4.2 | C8: {=IFERROR(INDEX(EDT!$C:$C,MATCH(B8,EDT!$A:$A,0)),"Código no existe")} -> Limpieza y normalización | D8: Registros nulos, duplicados o inconsistentes producen variables analíticas incorrectas. | E8: Técnicos | F8: Calidad | G8: 4 | H8: 3 | I8: =IF(OR(G8="",H8=""),"",G8*H8) -> 12 | J8: =IF(I8="","",IF(I8>='Criterios de riesgo'!$A$19,'Criterios de riesgo'!$B$19,IF(I8>='Criterios de riesgo'!$A$20,'Criterios de riesgo'!$B$20,IF(I8>='Criterios de riesgo'!$A$21,'Criterios de riesgo'!$B$21,'Criterios de riesgo'!$B$22)))) -> Alta | K8: Mitigar | L8: M1: Validaciones en la API al guardar datos. M2: Reglas de limpieza documentadas y log de registros descartados. | M8: Diferencias entre el cálculo manual de control y el ETL (casos de prueba del ETL) | N8: Nicole Marchant | O8: Fase 2 | P8: Abierto
A9: R-05 | B9: 1.5.1 | C9: {=IFERROR(INDEX(EDT!$C:$C,MATCH(B9,EDT!$A:$A,0)),"Código no existe")} -> Diseño del prompt y restricciones éticas | D9: La IA entrega interpretaciones que parecen diagnósticos psicológicos o afirma datos incorrectos. | E9: Técnicos | F9: Fiabilidad | G9: 5 | H9: 3 | I9: =IF(OR(G9="",H9=""),"",G9*H9) -> 15 | J9: =IF(I9="","",IF(I9>='Criterios de riesgo'!$A$19,'Criterios de riesgo'!$B$19,IF(I9>='Criterios de riesgo'!$A$20,'Criterios de riesgo'!$B$20,IF(I9>='Criterios de riesgo'!$A$21,'Criterios de riesgo'!$B$21,'Criterios de riesgo'!$B$22)))) -> Extrema | K9: Mitigar | L9: M1: Prompt con restricciones explícitas y ejemplos de respuesta. M2: Aviso visible en la interfaz. M3: Casos de prueba de la IA con revisión humana. | M9: Respuestas con términos clínicos o afirmaciones no sustentadas | N9: Katherine Rubilar | O9: Fase 2 | P9: Abierto
A10: R-06 | B10: 1.5.3 | C10: {=IFERROR(INDEX(EDT!$C:$C,MATCH(B10,EDT!$A:$A,0)),"Código no existe")} -> Análisis de perfil lector y recepción de obra | D10: Variables analíticas poco significativas generan interpretaciones genéricas y de bajo valor para el usuario. | E10: Técnicos | F10: Desempeño | G10: 3 | H10: 3 | I10: =IF(OR(G10="",H10=""),"",G10*H10) -> 9 | J10: =IF(I10="","",IF(I10>='Criterios de riesgo'!$A$19,'Criterios de riesgo'!$B$19,IF(I10>='Criterios de riesgo'!$A$20,'Criterios de riesgo'!$B$20,IF(I10>='Criterios de riesgo'!$A$21,'Criterios de riesgo'!$B$21,'Criterios de riesgo'!$B$22)))) -> Media | K10: Mitigar | L10: M1: Definir las variables con ejemplos de interpretación esperada. M2: Probar con perfiles simulados contrastantes. | M10: Perfiles distintos reciben interpretaciones casi iguales | N10: Nicole Marchant | O10: Fase 2 | P10: Abierto
A11: R-07 | B11: 1.6.1 | C11: {=IFERROR(INDEX(EDT!$C:$C,MATCH(B11,EDT!$A:$A,0)),"Código no existe")} -> Pruebas unitarias y de API | D11: Conflictos en el repositorio o cambios sin revisión provocan pérdida de código o versiones rotas. | E11: Técnicos | F11: Fiabilidad | G11: 3 | H11: 2 | I11: =IF(OR(G11="",H11=""),"",G11*H11) -> 6 | J11: =IF(I11="","",IF(I11>='Criterios de riesgo'!$A$19,'Criterios de riesgo'!$B$19,IF(I11>='Criterios de riesgo'!$A$20,'Criterios de riesgo'!$B$20,IF(I11>='Criterios de riesgo'!$A$21,'Criterios de riesgo'!$B$21,'Criterios de riesgo'!$B$22)))) -> Media | K11: Evitar | L11: E1: Ramas por funcionalidad, pull requests obligatorios y rama principal protegida. | M11: Merge directo a la rama principal o build roto | N11: Nicole Marchant | O11: Todas | P11: Abierto
A12: R-08 | B12: 1.5.2 | C12: {=IFERROR(INDEX(EDT!$C:$C,MATCH(B12,EDT!$A:$A,0)),"Código no existe")} -> Servicio de integración con el modelo de lenguaje (Ollama) | D12: Caídas, lentitud o falta de recursos del servicio de IA local (Ollama) detienen el análisis. | E12: Externos | F12: Proveedores | G12: 4 | H12: 3 | I12: =IF(OR(G12="",H12=""),"",G12*H12) -> 12 | J12: =IF(I12="","",IF(I12>='Criterios de riesgo'!$A$19,'Criterios de riesgo'!$B$19,IF(I12>='Criterios de riesgo'!$A$20,'Criterios de riesgo'!$B$20,IF(I12>='Criterios de riesgo'!$A$21,'Criterios de riesgo'!$B$21,'Criterios de riesgo'!$B$22)))) -> Alta | K12: Mitigar | L12: M1: Servicio desacoplado con respuesta de respaldo si la IA falla. M2: Reintentos, control de concurrencia y tiempos de espera configurados. | M12: Errores o tiempos de espera del servicio de IA | N12: Nicole Marchant | O12: Fase 2 | P12: Abierto
A13: R-09 | B13: 1.3.2 | C13: {=IFERROR(INDEX(EDT!$C:$C,MATCH(B13,EDT!$A:$A,0)),"Código no existe")} -> Catálogo y búsqueda de libros | D13: Límites o datos incompletos de la API externa de libros afectan la búsqueda del catálogo. | E13: Externos | F13: Proveedores | G13: 3 | H13: 3 | I13: =IF(OR(G13="",H13=""),"",G13*H13) -> 9 | J13: =IF(I13="","",IF(I13>='Criterios de riesgo'!$A$19,'Criterios de riesgo'!$B$19,IF(I13>='Criterios de riesgo'!$A$20,'Criterios de riesgo'!$B$20,IF(I13>='Criterios de riesgo'!$A$21,'Criterios de riesgo'!$B$21,'Criterios de riesgo'!$B$22)))) -> Media | K13: Mitigar | L13: M1: Carga inicial de un set de libros en la base local. M2: Caché de resultados consultados. | M13: Búsquedas sin resultados o errores de cuota | N13: Nicole Marchant | O13: Fase 1 | P13: Abierto
A14: R-10 | B14: 1.6.3 | C14: {=IFERROR(INDEX(EDT!$C:$C,MATCH(B14,EDT!$A:$A,0)),"Código no existe")} -> Seguridad y protección de datos | D14: Una filtración de datos personales o emocionales incumple la Ley 19.628 / 21.719 y afecta la confianza. | E14: Externos | F14: Normativos y legales | G14: 5 | H14: 2 | I14: =IF(OR(G14="",H14=""),"",G14*H14) -> 10 | J14: =IF(I14="","",IF(I14>='Criterios de riesgo'!$A$19,'Criterios de riesgo'!$B$19,IF(I14>='Criterios de riesgo'!$A$20,'Criterios de riesgo'!$B$20,IF(I14>='Criterios de riesgo'!$A$21,'Criterios de riesgo'!$B$21,'Criterios de riesgo'!$B$22)))) -> Alta | K14: Mitigar | L14: M1: Hash de contraseñas y credenciales en variables de entorno. M2: Seudonimización en la capa analítica. M3: Consentimiento explícito al registrarse. | M14: Credenciales en el repositorio o datos identificables en la capa analítica | N14: Nicole Marchant | O14: Todas | P14: Abierto
A15: R-11 | B15: 1.4.1 | C15: {=IFERROR(INDEX(EDT!$C:$C,MATCH(B15,EDT!$A:$A,0)),"Código no existe")} -> Extracción de datos operacionales | D15: El volumen de datos reales de usuarios no alcanza para que el ETL y la IA muestren patrones. | E15: Externos | F15: Usuarios | G15: 3 | H15: 4 | I15: =IF(OR(G15="",H15=""),"",G15*H15) -> 12 | J15: =IF(I15="","",IF(I15>='Criterios de riesgo'!$A$19,'Criterios de riesgo'!$B$19,IF(I15>='Criterios de riesgo'!$A$20,'Criterios de riesgo'!$B$20,IF(I15>='Criterios de riesgo'!$A$21,'Criterios de riesgo'!$B$21,'Criterios de riesgo'!$B$22)))) -> Alta | K15: Aceptar | L15: A1: Se acepta el riesgo; plan de contingencia con datos simulados identificados con prefijo test_ y documentados. | M15: Menos de 30 experiencias de lectura registradas al inicio de S8 | N15: Katherine Rubilar | O15: Fase 2 | P15: Abierto
A16: R-12 | B16: 1.1.3 | C16: {=IFERROR(INDEX(EDT!$C:$C,MATCH(B16,EDT!$A:$A,0)),"Código no existe")} -> Asignación de roles y responsabilidades | D16: Carga académica o laboral de un integrante reduce su disponibilidad y atrasa sus paquetes de trabajo. | E16: Organizacionales | F16: Recursos | G16: 4 | H16: 3 | I16: =IF(OR(G16="",H16=""),"",G16*H16) -> 12 | J16: =IF(I16="","",IF(I16>='Criterios de riesgo'!$A$19,'Criterios de riesgo'!$B$19,IF(I16>='Criterios de riesgo'!$A$20,'Criterios de riesgo'!$B$20,IF(I16>='Criterios de riesgo'!$A$21,'Criterios de riesgo'!$B$21,'Criterios de riesgo'!$B$22)))) -> Alta | K16: Mitigar | L16: M1: Revisión cruzada de pull requests para que dos personas conozcan cada módulo. M2: Reasignación de tareas en la reunión semanal. | M16: Tareas sin avance durante una semana | N16: Katherine Rubilar | O16: Todas | P16: Abierto
... A20: R-16 | B20: 1.1.5 | C20: {=IFERROR(INDEX(EDT!$C:$C,MATCH(B20,EDT!$A:$A,0)),"Código no existe")} -> Seguimiento y control del avance | D20: Seguimiento o comunicación insuficientes impiden detectar atrasos a tiempo. | E20: Gestión de proyecto | F20: Control y seguimiento | G20: 3 | H20: 2 | I20: =IF(OR(G20="",H20=""),"",G20*H20) -> 6 | J20: =IF(I20="","",IF(I20>='Criterios de riesgo'!$A$19,'Criterios de riesgo'!$B$19,IF(I20>='Criterios de riesgo'!$A$20,'Criterios de riesgo'!$B$20,IF(I20>='Criterios de riesgo'!$A$21,'Criterios de riesgo'!$B$21,'Criterios de riesgo'!$B$22)))) -> Media | K20: Mitigar | L20: M1: Reunión semanal de 30 minutos y tablero de sprints en Jira. M2: Revisión del registro de riesgos al cierre de cada fase. | M20: Reunión semanal omitida o tablero desactualizado | N20: Katherine Rubilar | O20: Todas | P20: Abierto

Sheet Mapa de calor
A1: Mapa de calor de riesgos
A2: Cada celda lista los riesgos del registro con esa combinación de probabilidad e impacto.
C4: IMPACTO
C5: 1 Insignificante | D5: 2 Menor | E5: 3 Moderado | F5: 4 Grave | G5: 5 Muy grave
A6: PROBABILIDAD | B6: 5 Muy alta | C6: {=TEXTJOIN(", ",TRUE(),IF(('Registro de riesgos'!$G$5:$G$24=1)*('Registro de riesgos'!$H$5:$H$24=5),'Registro de riesgos'!$A$5:$A$24,""))} | D6: {=TEXTJOIN(", ",TRUE(),IF(('Registro de riesgos'!$G$5:$G$24=2)*('Registro de riesgos'!$H$5:$H$24=5),'Registro de riesgos'!$A$5:$A$24,""))} | E6: {=TEXTJOIN(", ",TRUE(),IF(('Registro de riesgos'!$G$5:$G$24=3)*('Registro de riesgos'!$H$5:$H$24=5),'Registro de riesgos'!$A$5:$A$24,""))} | F6: {=TEXTJOIN(", ",TRUE(),IF(('Registro de riesgos'!$G$5:$G$24=4)*('Registro de riesgos'!$H$5:$H$24=5),'Registro de riesgos'!$A$5:$A$24,""))} | G6: {=TEXTJOIN(", ",TRUE(),IF(('Registro de riesgos'!$G$5:$G$24=5)*('Registro de riesgos'!$H$5:$H$24=5),'Registro de riesgos'!$A$5:$A$24,""))}
B7: 4 Alta | C7: {=TEXTJOIN(", ",TRUE(),IF(('Registro de riesgos'!$G$5:$G$24=1)*('Registro de riesgos'!$H$5:$H$24=4),'Registro de riesgos'!$A$5:$A$24,""))} | D7: {=TEXTJOIN(", ",TRUE(),IF(('Registro de riesgos'!$G$5:$G$24=2)*('Registro de riesgos'!$H$5:$H$24=4),'Registro de riesgos'!$A$5:$A$24,""))} | E7: {=TEXTJOIN(", ",TRUE(),IF(('Registro de riesgos'!$G$5:$G$24=3)*('Registro de riesgos'!$H$5:$H$24=4),'Registro de riesgos'!$A$5:$A$24,""))} -> R-11 | F7: {=TEXTJOIN(", ",TRUE(),IF(('Registro de riesgos'!$G$5:$G$24=4)*('Registro de riesgos'!$H$5:$H$24=4),'Registro de riesgos'!$A$5:$A$24,""))} -> R-15 | G7: {=TEXTJOIN(", ",TRUE(),IF(('Registro de riesgos'!$G$5:$G$24=5)*('Registro de riesgos'!$H$5:$H$24=4),'Registro de riesgos'!$A$5:$A$24,""))} -> R-14
B8: 3 Media | C8: {=TEXTJOIN(", ",TRUE(),IF(('Registro de riesgos'!$G$5:$G$24=1)*('Registro de riesgos'!$H$5:$H$24=3),'Registro de riesgos'!$A$5:$A$24,""))} | D8: {=TEXTJOIN(", ",TRUE(),IF(('Registro de riesgos'!$G$5:$G$24=2)*('Registro de riesgos'!$H$5:$H$24=3),'Registro de riesgos'!$A$5:$A$24,""))} | E8: {=TEXTJOIN(", ",TRUE(),IF(('Registro de riesgos'!$G$5:$G$24=3)*('Registro de riesgos'!$H$5:$H$24=3),'Registro de riesgos'!$A$5:$A$24,""))} -> R-06, R-09, R-13 | F8: {=TEXTJOIN(", ",TRUE(),IF(('Registro de riesgos'!$G$5:$G$24=4)*('Registro de riesgos'!$H$5:$H$24=3),'Registro de riesgos'!$A$5:$A$24,""))} -> R-01, R-02, R-03, R-04, R-08, R-12 | G8: {=TEXTJOIN(", ",TRUE(),IF(('Registro de riesgos'!$G$5:$G$24=5)*('Registro de riesgos'!$H$5:$H$24=3),'Registro de riesgos'!$A$5:$A$24,""))} -> R-05
B9: 2 Baja | C9: {=TEXTJOIN(", ",TRUE(),IF(('Registro de riesgos'!$G$5:$G$24=1)*('Registro de riesgos'!$H$5:$H$24=2),'Registro de riesgos'!$A$5:$A$24,""))} | D9: {=TEXTJOIN(", ",TRUE(),IF(('Registro de riesgos'!$G$5:$G$24=2)*('Registro de riesgos'!$H$5:$H$24=2),'Registro de riesgos'!$A$5:$A$24,""))} | E9: {=TEXTJOIN(", ",TRUE(),IF(('Registro de riesgos'!$G$5:$G$24=3)*('Registro de riesgos'!$H$5:$H$24=2),'Registro de riesgos'!$A$5:$A$24,""))} -> R-07, R-16 | F9: {=TEXTJOIN(", ",TRUE(),IF(('Registro de riesgos'!$G$5:$G$24=4)*('Registro de riesgos'!$H$5:$H$24=2),'Registro de riesgos'!$A$5:$A$24,""))} | G9: {=TEXTJOIN(", ",TRUE(),IF(('Registro de riesgos'!$G$5:$G$24=5)*('Registro de riesgos'!$H$5:$H$24=2),'Registro de riesgos'!$A$5:$A$24,""))} -> R-10
B10: 1 Muy baja | C10: {=TEXTJOIN(", ",TRUE(),IF(('Registro de riesgos'!$G$5:$G$24=1)*('Registro de riesgos'!$H$5:$H$24=1),'Registro de riesgos'!$A$5:$A$24,""))} | D10: {=TEXTJOIN(", ",TRUE(),IF(('Registro de riesgos'!$G$5:$G$24=2)*('Registro de riesgos'!$H$5:$H$24=1),'Registro de riesgos'!$A$5:$A$24,""))} | E10: {=TEXTJOIN(", ",TRUE(),IF(('Registro de riesgos'!$G$5:$G$24=3)*('Registro de riesgos'!$H$5:$H$24=1),'Registro de riesgos'!$A$5:$A$24,""))} | F10: {=TEXTJOIN(", ",TRUE(),IF(('Registro de riesgos'!$G$5:$G$24=4)*('Registro de riesgos'!$H$5:$H$24=1),'Registro de riesgos'!$A$5:$A$24,""))} | G10: {=TEXTJOIN(", ",TRUE(),IF(('Registro de riesgos'!$G$5:$G$24=5)*('Registro de riesgos'!$H$5:$H$24=1),'Registro de riesgos'!$A$5:$A$24,""))}
B12: Resumen | C12: N.º de riesgos
B13: Extrema | C13: =COUNTIF('Registro de riesgos'!$J$5:$J$24,B13) -> 3
B14: Alta | C14: =COUNTIF('Registro de riesgos'!$J$5:$J$24,B14) -> 8
B15: Media | C15: =COUNTIF('Registro de riesgos'!$J$5:$J$24,B15) -> 5
B16: Baja | C16: =COUNTIF('Registro de riesgos'!$J$5:$J$24,B16) -> 0
B17: Total | C17: =SUM(C13:C16) -> 16

Sheet RBS
A1: Estructura de desglose de riesgos (RBS)
A2: Categorías de riesgo del proyecto y riesgos identificados. Las subcategorías con 0 riesgos se mantienen deliberadamente para monitoreo futuro.
A4: Nivel 1 — Categoría | B4: Nivel 2 — Subcategoría | C4: Riesgos | D4: N.º de riesgos | E4: Puntuación máxima
A5: 1.0 Técnicos | B5: Requisitos | C5: R-01 Requerimientos ambiguos | D5: =COUNTIFS('Registro de riesgos'!$E$5:$E$24,"Técnicos",'Registro de riesgos'!$F$5:$F$24,B5) -> 1 | E5: =IF(D5=0,"",MAXIFS('Registro de riesgos'!$I$5:$I$24,'Registro de riesgos'!$E$5:$E$24,"Técnicos",'Registro de riesgos'!$F$5:$F$24,B5)) -> 12
B6: Tecnología | C6: R-02 Modelo de datos deficiente | D6: =COUNTIFS('Registro de riesgos'!$E$5:$E$24,"Técnicos",'Registro de riesgos'!$F$5:$F$24,B6) -> 1 | E6: =IF(D6=0,"",MAXIFS('Registro de riesgos'!$I$5:$I$24,'Registro de riesgos'!$E$5:$E$24,"Técnicos",'Registro de riesgos'!$F$5:$F$24,B6)) -> 12
B7: Complejidad | C7: — | D7: =COUNTIFS('Registro de riesgos'!$E$5:$E$24,"Técnicos",'Registro de riesgos'!$F$5:$F$24,B7) -> 0 | E7: =IF(D7=0,"",MAXIFS('Registro de riesgos'!$I$5:$I$24,'Registro de riesgos'!$E$5:$E$24,"Técnicos",'Registro de riesgos'!$F$5:$F$24,B7))
B8: Interfaces | C8: R-03 Fallas de integración | D8: =COUNTIFS('Registro de riesgos'!$E$5:$E$24,"Técnicos",'Registro de riesgos'!$F$5:$F$24,B8) -> 1 | E8: =IF(D8=0,"",MAXIFS('Registro de riesgos'!$I$5:$I$24,'Registro de riesgos'!$E$5:$E$24,"Técnicos",'Registro de riesgos'!$F$5:$F$24,B8)) -> 12
B9: Desempeño | C9: R-06 Interpretaciones genéricas | D9: =COUNTIFS('Registro de riesgos'!$E$5:$E$24,"Técnicos",'Registro de riesgos'!$F$5:$F$24,B9) -> 1 | E9: =IF(D9=0,"",MAXIFS('Registro de riesgos'!$I$5:$I$24,'Registro de riesgos'!$E$5:$E$24,"Técnicos",'Registro de riesgos'!$F$5:$F$24,B9)) -> 9
B10: Fiabilidad | C10: R-05 IA con lenguaje de diagnóstico R-07 Pérdida de código | D10: =COUNTIFS('Registro de riesgos'!$E$5:$E$24,"Técnicos",'Registro de riesgos'!$F$5:$F$24,B10) -> 2 | E10: =IF(D10=0,"",MAXIFS('Registro de riesgos'!$I$5:$I$24,'Registro de riesgos'!$E$5:$E$24,"Técnicos",'Registro de riesgos'!$F$5:$F$24,B10)) -> 15
B11: Calidad | C11: R-04 Datos sucios en el ETL | D11: =COUNTIFS('Registro de riesgos'!$E$5:$E$24,"Técnicos",'Registro de riesgos'!$F$5:$F$24,B11) -> 1 | E11: =IF(D11=0,"",MAXIFS('Registro de riesgos'!$I$5:$I$24,'Registro de riesgos'!$E$5:$E$24,"Técnicos",'Registro de riesgos'!$F$5:$F$24,B11)) -> 12
A12: 2.0 Externos | B12: Proveedores | C12: R-08 Disponibilidad del servicio de IA R-09 Dependencia de la API de libros | D12: =COUNTIFS('Registro de riesgos'!$E$5:$E$24,"Externos",'Registro de riesgos'!$F$5:$F$24,B12) -> 2 | E12: =IF(D12=0,"",MAXIFS('Registro de riesgos'!$I$5:$I$24,'Registro de riesgos'!$E$5:$E$24,"Externos",'Registro de riesgos'!$F$5:$F$24,B12)) -> 12
B13: Normativos y legales | C13: R-10 Filtración de datos personales | D13: =COUNTIFS('Registro de riesgos'!$E$5:$E$24,"Externos",'Registro de riesgos'!$F$5:$F$24,B13) -> 1 | E13: =IF(D13=0,"",MAXIFS('Registro de riesgos'!$I$5:$I$24,'Registro de riesgos'!$E$5:$E$24,"Externos",'Registro de riesgos'!$F$5:$F$24,B13)) -> 10
B14: Usuarios | C14: R-11 Pocos datos reales | D14: =COUNTIFS('Registro de riesgos'!$E$5:$E$24,"Externos",'Registro de riesgos'!$F$5:$F$24,B14) -> 1 | E14: =IF(D14=0,"",MAXIFS('Registro de riesgos'!$I$5:$I$24,'Registro de riesgos'!$E$5:$E$24,"Externos",'Registro de riesgos'!$F$5:$F$24,B14)) -> 12
A15: 3.0 Organizacionales | B15: Recursos | C15: R-12 Baja disponibilidad de un integrante R-13 Curva de aprendizaje | D15: =COUNTIFS('Registro de riesgos'!$E$5:$E$24,"Organizacionales",'Registro de riesgos'!$F$5:$F$24,B15) -> 2 | E15: =IF(D15=0,"",MAXIFS('Registro de riesgos'!$I$5:$I$24,'Registro de riesgos'!$E$5:$E$24,"Organizacionales",'Registro de riesgos'!$F$5:$F$24,B15)) -> 12
B16: Interdependencias | C16: — | D16: =COUNTIFS('Registro de riesgos'!$E$5:$E$24,"Organizacionales",'Registro de riesgos'!$F$5:$F$24,B16) -> 0 | E16: =IF(D16=0,"",MAXIFS('Registro de riesgos'!$I$5:$I$24,'Registro de riesgos'!$E$5:$E$24,"Organizacionales",'Registro de riesgos'!$F$5:$F$24,B16))
B17: Priorización | C17: — | D17: =COUNTIFS('Registro de riesgos'!$E$5:$E$24,"Organizacionales",'Registro de riesgos'!$F$5:$F$24,B17) -> 0 | E17: =IF(D17=0,"",MAXIFS('Registro de riesgos'!$I$5:$I$24,'Registro de riesgos'!$E$5:$E$24,"Organizacionales",'Registro de riesgos'!$F$5:$F$24,B17))
A18: 4.0 Gestión de proyecto | B18: Estimación | C18: R-15 Cronograma comprimido | D18: =COUNTIFS('Registro de riesgos'!$E$5:$E$24,"Gestión de proyecto",'Registro de riesgos'!$F$5:$F$24,B18) -> 1 | E18: =IF(D18=0,"",MAXIFS('Registro de riesgos'!$I$5:$I$24,'Registro de riesgos'!$E$5:$E$24,"Gestión de proyecto",'Registro de riesgos'!$F$5:$F$24,B18)) -> 16
B19: Planificación | C19: R-14 Crecimiento del alcance | D19: =COUNTIFS('Registro de riesgos'!$E$5:$E$24,"Gestión de proyecto",'Registro de riesgos'!$F$5:$F$24,B19) -> 1 | E19: =IF(D19=0,"",MAXIFS('Registro de riesgos'!$I$5:$I$24,'Registro de riesgos'!$E$5:$E$24,"Gestión de proyecto",'Registro de riesgos'!$F$5:$F$24,B19)) -> 20
B20: Control y seguimiento | C20: R-16 Seguimiento insuficiente | D20: =COUNTIFS('Registro de riesgos'!$E$5:$E$24,"Gestión de proyecto",'Registro de riesgos'!$F$5:$F$24,B20) -> 1 | E20: =IF(D20=0,"",MAXIFS('Registro de riesgos'!$I$5:$I$24,'Registro de riesgos'!$E$5:$E$24,"Gestión de proyecto",'Registro de riesgos'!$F$5:$F$24,B20)) -> 6
B21: Comunicaciones | C21: — | D21: =COUNTIFS('Registro de riesgos'!$E$5:$E$24,"Gestión de proyecto",'Registro de riesgos'!$F$5:$F$24,B21) -> 0 | E21: =IF(D21=0,"",MAXIFS('Registro de riesgos'!$I$5:$I$24,'Registro de riesgos'!$E$5:$E$24,"Gestión de proyecto",'Registro de riesgos'!$F$5:$F$24,B21))
